[2025-09-25T19:56:18.288+0000] {local_task_job_runner.py:120} INFO - ::group::Pre task execution logs
[2025-09-25T19:56:18.362+0000] {taskinstance.py:2076} INFO - Dependencies all met for dep_context=non-requeueable deps ti=<TaskInstance: robot_powershell_host_run.run_robot_tests manual__2025-09-25T19:56:17.478086+00:00 [queued]>
[2025-09-25T19:56:18.378+0000] {taskinstance.py:2076} INFO - Dependencies all met for dep_context=requeueable deps ti=<TaskInstance: robot_powershell_host_run.run_robot_tests manual__2025-09-25T19:56:17.478086+00:00 [queued]>
[2025-09-25T19:56:18.379+0000] {taskinstance.py:2306} INFO - Starting attempt 1 of 1
[2025-09-25T19:56:18.403+0000] {taskinstance.py:2330} INFO - Executing <Task(WinRMOperator): run_robot_tests> on 2025-09-25 19:56:17.478086+00:00
[2025-09-25T19:56:18.420+0000] {logging_mixin.py:188} WARNING - /home/***/.local/lib/python3.12/site-packages/***/task/task_runner/standard_task_runner.py:62 DeprecationWarning: This process (pid=92) is multi-threaded, use of fork() may lead to deadlocks in the child.
[2025-09-25T19:56:18.423+0000] {standard_task_runner.py:64} INFO - Started process 93 to run task
[2025-09-25T19:56:18.419+0000] {standard_task_runner.py:90} INFO - Running: ['***', 'tasks', 'run', 'robot_powershell_host_run', 'run_robot_tests', 'manual__2025-09-25T19:56:17.478086+00:00', '--job-id', '4', '--raw', '--subdir', 'DAGS_FOLDER/robot_powershell_winrm.py', '--cfg-path', '/tmp/tmp05_hqvoj']
[2025-09-25T19:56:18.424+0000] {standard_task_runner.py:91} INFO - Job 4: Subtask run_robot_tests
[2025-09-25T19:56:18.551+0000] {task_command.py:426} INFO - Running <TaskInstance: robot_powershell_host_run.run_robot_tests manual__2025-09-25T19:56:17.478086+00:00 [running]> on host e55b74c958e6
[2025-09-25T19:56:18.730+0000] {taskinstance.py:2648} INFO - Exporting env vars: AIRFLOW_CTX_DAG_OWNER='***' AIRFLOW_CTX_DAG_ID='robot_powershell_host_run' AIRFLOW_CTX_TASK_ID='run_robot_tests' AIRFLOW_CTX_EXECUTION_DATE='2025-09-25T19:56:17.478086+00:00' AIRFLOW_CTX_TRY_NUMBER='1' AIRFLOW_CTX_DAG_RUN_ID='manual__2025-09-25T19:56:17.478086+00:00'
[2025-09-25T19:56:18.732+0000] {taskinstance.py:430} INFO - ::endgroup::
[2025-09-25T19:56:18.762+0000] {winrm.py:80} INFO - Hook not found, creating...
[2025-09-25T19:56:18.804+0000] {base.py:84} INFO - Using connection ID 'winrm_localhost' for task execution.
[2025-09-25T19:56:18.806+0000] {winrm.py:217} INFO - Establishing WinRM connection to host: localhost
[2025-09-25T19:56:18.815+0000] {winrm.py:222} ERROR - Error connecting to host: localhost, error: HTTPConnectionPool(host='localhost', port=5985): Max retries exceeded with url: /wsman (Caused by NewConnectionError('<urllib3.connection.HTTPConnection object at 0x71234adc5d00>: Failed to establish a new connection: [Errno 111] Connection refused'))
[2025-09-25T19:56:18.817+0000] {taskinstance.py:441} INFO - ::group::Post task execution logs
[2025-09-25T19:56:18.839+0000] {taskinstance.py:2905} ERROR - Task failed with exception
Traceback (most recent call last):
  File "/home/airflow/.local/lib/python3.12/site-packages/urllib3/connection.py", line 203, in _new_conn
    sock = connection.create_connection(
           ^^^^^^^^^^^^^^^^^^^^^^^^^^^^^
  File "/home/airflow/.local/lib/python3.12/site-packages/urllib3/util/connection.py", line 85, in create_connection
    raise err
  File "/home/airflow/.local/lib/python3.12/site-packages/urllib3/util/connection.py", line 73, in create_connection
    sock.connect(sa)
ConnectionRefusedError: [Errno 111] Connection refused

The above exception was the direct cause of the following exception:

Traceback (most recent call last):
  File "/home/airflow/.local/lib/python3.12/site-packages/urllib3/connectionpool.py", line 791, in urlopen
    response = self._make_request(
               ^^^^^^^^^^^^^^^^^^^
  File "/home/airflow/.local/lib/python3.12/site-packages/urllib3/connectionpool.py", line 497, in _make_request
    conn.request(
  File "/home/airflow/.local/lib/python3.12/site-packages/urllib3/connection.py", line 395, in request
    self.endheaders()
  File "/usr/local/lib/python3.12/http/client.py", line 1331, in endheaders
    self._send_output(message_body, encode_chunked=encode_chunked)
  File "/usr/local/lib/python3.12/http/client.py", line 1091, in _send_output
    self.send(msg)
  File "/usr/local/lib/python3.12/http/client.py", line 1035, in send
    self.connect()
  File "/home/airflow/.local/lib/python3.12/site-packages/urllib3/connection.py", line 243, in connect
    self.sock = self._new_conn()
                ^^^^^^^^^^^^^^^^
  File "/home/airflow/.local/lib/python3.12/site-packages/urllib3/connection.py", line 218, in _new_conn
    raise NewConnectionError(
urllib3.exceptions.NewConnectionError: <urllib3.connection.HTTPConnection object at 0x71234adc5d00>: Failed to establish a new connection: [Errno 111] Connection refused

The above exception was the direct cause of the following exception:

Traceback (most recent call last):
  File "/home/airflow/.local/lib/python3.12/site-packages/requests/adapters.py", line 667, in send
    resp = conn.urlopen(
           ^^^^^^^^^^^^^
  File "/home/airflow/.local/lib/python3.12/site-packages/urllib3/connectionpool.py", line 845, in urlopen
    retries = retries.increment(
              ^^^^^^^^^^^^^^^^^^
  File "/home/airflow/.local/lib/python3.12/site-packages/urllib3/util/retry.py", line 515, in increment
    raise MaxRetryError(_pool, url, reason) from reason  # type: ignore[arg-type]
    ^^^^^^^^^^^^^^^^^^^^^^^^^^^^^^^^^^^^^^^^^^^^^^^^^^^
urllib3.exceptions.MaxRetryError: HTTPConnectionPool(host='localhost', port=5985): Max retries exceeded with url: /wsman (Caused by NewConnectionError('<urllib3.connection.HTTPConnection object at 0x71234adc5d00>: Failed to establish a new connection: [Errno 111] Connection refused'))

During handling of the above exception, another exception occurred:

Traceback (most recent call last):
  File "/home/airflow/.local/lib/python3.12/site-packages/airflow/providers/microsoft/winrm/hooks/winrm.py", line 218, in get_conn
    self.client = self.winrm_protocol.open_shell()
                  ^^^^^^^^^^^^^^^^^^^^^^^^^^^^^^^^
  File "/home/airflow/.local/lib/python3.12/site-packages/winrm/protocol.py", line 193, in open_shell
    res = self.send_message(xmltodict.unparse(req))
          ^^^^^^^^^^^^^^^^^^^^^^^^^^^^^^^^^^^^^^^^^
  File "/home/airflow/.local/lib/python3.12/site-packages/winrm/protocol.py", line 263, in send_message
    resp = self.transport.send_message(message)
           ^^^^^^^^^^^^^^^^^^^^^^^^^^^^^^^^^^^^
  File "/home/airflow/.local/lib/python3.12/site-packages/winrm/transport.py", line 336, in send_message
    response = self._send_message_request(session, prepared_request)
               ^^^^^^^^^^^^^^^^^^^^^^^^^^^^^^^^^^^^^^^^^^^^^^^^^^^^^
  File "/home/airflow/.local/lib/python3.12/site-packages/winrm/transport.py", line 341, in _send_message_request
    response = session.send(prepared_request, timeout=self.read_timeout_sec)
               ^^^^^^^^^^^^^^^^^^^^^^^^^^^^^^^^^^^^^^^^^^^^^^^^^^^^^^^^^^^^^
  File "/home/airflow/.local/lib/python3.12/site-packages/requests/sessions.py", line 703, in send
    r = adapter.send(request, **kwargs)
        ^^^^^^^^^^^^^^^^^^^^^^^^^^^^^^^
  File "/home/airflow/.local/lib/python3.12/site-packages/requests/adapters.py", line 700, in send
    raise ConnectionError(e, request=request)
requests.exceptions.ConnectionError: HTTPConnectionPool(host='localhost', port=5985): Max retries exceeded with url: /wsman (Caused by NewConnectionError('<urllib3.connection.HTTPConnection object at 0x71234adc5d00>: Failed to establish a new connection: [Errno 111] Connection refused'))

During handling of the above exception, another exception occurred:

Traceback (most recent call last):
  File "/home/airflow/.local/lib/python3.12/site-packages/airflow/models/taskinstance.py", line 465, in _execute_task
    result = _execute_callable(context=context, **execute_callable_kwargs)
             ^^^^^^^^^^^^^^^^^^^^^^^^^^^^^^^^^^^^^^^^^^^^^^^^^^^^^^^^^^^^^
  File "/home/airflow/.local/lib/python3.12/site-packages/airflow/models/taskinstance.py", line 432, in _execute_callable
    return execute_callable(context=context, **execute_callable_kwargs)
           ^^^^^^^^^^^^^^^^^^^^^^^^^^^^^^^^^^^^^^^^^^^^^^^^^^^^^^^^^^^^
  File "/home/airflow/.local/lib/python3.12/site-packages/airflow/models/baseoperator.py", line 401, in wrapper
    return func(self, *args, **kwargs)
           ^^^^^^^^^^^^^^^^^^^^^^^^^^^
  File "/home/airflow/.local/lib/python3.12/site-packages/airflow/providers/microsoft/winrm/operators/winrm.py", line 92, in execute
    winrm_client = self.winrm_hook.get_conn()
                   ^^^^^^^^^^^^^^^^^^^^^^^^^^
  File "/home/airflow/.local/lib/python3.12/site-packages/airflow/providers/microsoft/winrm/hooks/winrm.py", line 223, in get_conn
    raise AirflowException(error_msg)
airflow.exceptions.AirflowException: Error connecting to host: localhost, error: HTTPConnectionPool(host='localhost', port=5985): Max retries exceeded with url: /wsman (Caused by NewConnectionError('<urllib3.connection.HTTPConnection object at 0x71234adc5d00>: Failed to establish a new connection: [Errno 111] Connection refused'))
[2025-09-25T19:56:18.856+0000] {taskinstance.py:1206} INFO - Marking task as FAILED. dag_id=robot_powershell_host_run, task_id=run_robot_tests, run_id=manual__2025-09-25T19:56:17.478086+00:00, execution_date=20250925T195617, start_date=20250925T195618, end_date=20250925T195618
[2025-09-25T19:56:18.876+0000] {standard_task_runner.py:110} ERROR - Failed to execute job 4 for task run_robot_tests (Error connecting to host: localhost, error: HTTPConnectionPool(host='localhost', port=5985): Max retries exceeded with url: /wsman (Caused by NewConnectionError('<urllib3.connection.HTTPConnection object at 0x71234adc5d00>: Failed to establish a new connection: [Errno 111] Connection refused')); 93)
[2025-09-25T19:56:18.922+0000] {local_task_job_runner.py:243} INFO - Task exited with return code 1
[2025-09-25T19:56:18.957+0000] {taskinstance.py:3503} INFO - 0 downstream tasks scheduled from follow-on schedule check
[2025-09-25T19:56:18.961+0000] {local_task_job_runner.py:222} INFO - ::endgroup::
